<?xml version="1.0"?>
<robot name="my_bot" xmlns:xacro="http://www.ros.org/wiki/xacro">


  <link name="base_link">
    <visual>
      
      <geometry>
        <mesh filename="file:///home/parsa/ros2_urdf_ws/src/my_robot_description/meshes//Body.dae" scale="0.01 0.01 0.01"/>
        
      </geometry>
      <origin xyz="-1.73 2.76 0.1" rpy="-1.57 0.0 -1.57"/>
    
    </visual>
    <collision>
      <geometry>
        <mesh filename="file:///home/parsa/ros2_urdf_ws/src/my_robot_description/meshes//Body.dae" scale="0.01 0.01 0.01"/>
      </geometry>
      <origin xyz="-1.73 2.76 0.1" rpy="-1.57 0.0 -1.57"/>
    </collision>
    <inertial>
      <origin xyz="0.0 0.0 0.0" rpy="0.0 0.0 0.0"/>
      <mass value="0.07354"/>
      <inertia ixx="0.0000011237" ixy="0.00000000532" ixz="0.00000000021" iyy="0.0000022452" iyz="0.000000003206" izz="0.0000032271"/>
    </inertial>
    

  </link>





  <link name="torso_joint_f_1">
    <visual>  
      <geometry>
        <mesh filename="file:///home/parsa/ros2_urdf_ws/src/my_robot_description/meshes//torso_joint_f.dae" scale="0.01 0.01 0.01"/>
      </geometry>
      <origin xyz="-0.935 -0.93 -0.895" rpy="0 0 0"/>
    </visual>
    <collision>
      <geometry>
        <mesh filename="file:///home/parsa/ros2_urdf_ws/src/my_robot_description/meshes//torso_joint_f.dae" scale="0.01 0.01 0.01"/>
      </geometry>
      <origin xyz="-0.935 -0.93 -0.895" rpy="0 0 0"/>
    </collision>
    <inertial>
      <origin xyz="0.0 0.0 0.0" rpy="0.0 0.0 0.0"/>
      <mass value="0.014413"/>
      <inertia ixx="0.0002" ixy="0.000000010485" ixz="0.0000077413" iyy="0.0001467" iyz="0.0000020864" izz="0.0002036"/>
    </inertial>
    

  

  </link>
  <joint name="base_torso_f_1" type="revolute">
    <parent link="base_link" />
    <child link="torso_joint_f_1" />
    <origin xyz="0.435 -0.648 0.894" rpy="0.0 0.0 -3.14"/>
    <axis xyz="0 0 1"/>
    <limit lower="-1.57" upper="1.57" velocity="100" effort="100"/>
  </joint>



  <link name="torso_joint_f_2">
    <visual>  
      <geometry>
        <mesh filename="file:///home/parsa/ros2_urdf_ws/src/my_robot_description/meshes//torso_joint_f.dae" scale="0.01 0.01 0.01"/>
      </geometry>
      <origin xyz="-0.935 -0.93 -0.895" rpy="0 0 0"/>
    </visual>
    <collision>
          <geometry>
        <mesh filename="file:///home/parsa/ros2_urdf_ws/src/my_robot_description/meshes//torso_joint_f.dae" scale="0.01 0.01 0.01"/>
      </geometry>
      <origin xyz="-0.935 -0.93 -0.895" rpy="0 0 0"/>
    </collision>

    <inertial>
      <origin xyz="0.0 0.0 0.0" rpy="0.0 0.0 0.0"/>
      <mass value="0.014413"/>
      <inertia ixx="0.0002" ixy="0.000000010485" ixz="0.0000077413" iyy="0.0001467" iyz="0.0000020864" izz="0.0002036"/>
    </inertial>
    
  

  </link>
  <joint name="base_torso_f_2" type="revolute">
    <parent link="base_link" />
    <child link="torso_joint_f_2" />
    <origin xyz="-0.428 -0.658 0.894" rpy="0.0 0.0 -3.14"/>
    <axis xyz="0 0 1"/>
    <limit lower="-1.57" upper="1.57" velocity="100" effort="100"/>
  </joint>


  <link name="torso_joint_b_1">
    <visual>  
      <geometry>
        <mesh filename="file:///home/parsa/ros2_urdf_ws/src/my_robot_description/meshes//torso_joint_b.dae" scale="0.01 0.01 0.01"/>
      </geometry>
      <origin xyz="-1.43 -0.93 -0.895" rpy="0 0 0"/>
    </visual>
    <collision>
        <geometry>
        <mesh filename="file:///home/parsa/ros2_urdf_ws/src/my_robot_description/meshes//torso_joint_b.dae" scale="0.01 0.01 0.01"/>
      </geometry>
      <origin xyz="-1.43 -0.93 -0.895" rpy="0 0 0"/> 
    </collision>

    <inertial>
      <origin xyz="0.0 0.0 0.0" rpy="0.0 0.0 0.0"/>
      <mass value="0.014413"/>
      <inertia ixx="0.0002" ixy="-0.000000010753" ixz="-0.0000077417" iyy="0.0001467" iyz="0.0000020774" izz="0.0002036"/>
    </inertial>
    
  

  </link>
  <joint name="base_torso_b_1" type="revolute">
    <parent link="base_link" />
    <child link="torso_joint_b_1" />
    <origin xyz="-0.425 0.53 0.894" rpy="0.0 0.0 0.0"/>
    <axis xyz="0 0 1"/>
    <limit lower="-1.57" upper="1.57" velocity="100" effort="100"/>
  </joint>




  <link name="torso_joint_b_2">
    <visual>  
      <geometry>
        <mesh filename="file:///home/parsa/ros2_urdf_ws/src/my_robot_description/meshes//torso_joint_b.dae" scale="0.01 0.01 0.01"/>
      </geometry>
      <origin xyz="-1.43 -0.93 -0.895" rpy="0 0 0"/>
    </visual>

      <collision>
        <geometry>
        <mesh filename="file:///home/parsa/ros2_urdf_ws/src/my_robot_description/meshes//torso_joint_b.dae" scale="0.01 0.01 0.01"/>
      </geometry>
      <origin xyz="-1.43 -0.93 -0.895" rpy="0 0 0"/> 
    </collision>

    <inertial>
      <origin xyz="0.0 0.0 0.0" rpy="0.0 0.0 0.0"/>
      <mass value="0.014413"/>
      <inertia ixx="0.0002" ixy="-0.000000010753" ixz="-0.0000077417" iyy="0.0001467" iyz="0.0000020774" izz="0.0002036"/>
    </inertial>
  

  </link>
  <joint name="base_torso_b_2" type="revolute">
    <parent link="base_link" />
    <child link="torso_joint_b_2" />
    <origin xyz="0.437 0.53 0.894" rpy="0.0 0.0 0.0"/>
    <axis xyz="0 0 1"/>
    <limit lower="-1.57" upper="1.57" velocity="100" effort="100"/>
  </joint>
  <link name="femur_1">
    <visual>  
      <geometry>
        <mesh filename="file:///home/parsa/ros2_urdf_ws/src/my_robot_description/meshes//femur.dae" scale="0.01 0.01 0.01"/>
      </geometry>
      <origin xyz="-0.77 -1.14 -0.8" rpy="0 0 0"/>
    </visual>

    <collision>
      <geometry>
        <mesh filename="file:///home/parsa/ros2_urdf_ws/src/my_robot_description/meshes//femur.dae" scale="0.01 0.01 0.01"/>
      </geometry>
      <origin xyz="-0.77 -1.14 -0.8" rpy="0 0 0"/>
      </collision>

      <inertial>
        <origin xyz="0.0 0.0 0.0" rpy="0.0 0.0 0.0"/>
        <mass value="0.006043"/>
        <inertia ixx="0.0000835711" ixy="0.00000010975" ixz="-0.000000004152" iyy="0.000000001607" iyz="-0.0002288" izz="-0.000000001607"/>
      </inertial>
      
  </link>
  <joint name="torso_f_1_femur_1" type="revolute">
    <parent link="torso_joint_f_1" />
    <child link="femur_1" />
    <origin xyz="-0.197 0.229 -0.043" rpy="0.0 0.0 0.0"/>
    <axis xyz="1 0 0"/>
    <limit lower="-1.57" upper="1.57" velocity="100" effort="100"/>
  </joint>


  <link name="femur_2">
    <visual>  
      <geometry>
        <mesh filename="file:///home/parsa/ros2_urdf_ws/src/my_robot_description/meshes//femur.dae" scale="0.01 0.01 0.01"/>
      </geometry>
      <origin xyz="-0.73 -1.17 -0.8" rpy="0 0 0"/>
    </visual>
    <collision>
      <geometry>
        <mesh filename="file:///home/parsa/ros2_urdf_ws/src/my_robot_description/meshes//femur.dae" scale="0.01 0.01 0.01"/>
      </geometry>
      <origin xyz="-0.73 -1.17 -0.8" rpy="0 0 0"/>
      
    </collision>
      <inertial>
        <origin xyz="0.0 0.0 0.0" rpy="0.0 0.0 0.0"/>
        <mass value="0.006043"/>
        <inertia ixx="0.0000835711" ixy="0.00000010975" ixz="-0.000000004152" iyy="0.000000001607" iyz="-0.0002288" izz="-0.000000001607"/>
      </inertial>



  </link>

  <joint name="torso_f_2_femur_2" type="revolute">
    <parent link="torso_joint_f_2" />
    <child link="femur_2" />
    <origin xyz="-0.187 0.231 -0.042" rpy="0.0 0.0 0.0"/>
    <axis xyz="1 0 0"/>
    <limit lower="-1.57" upper="1.57" velocity="100" effort="100"/>
  </joint>



  <link name="femur_3">
    <visual>  
      <geometry>
        <mesh filename="file:///home/parsa/ros2_urdf_ws/src/my_robot_description/meshes//femur.dae" scale="0.01 0.01 0.01"/>
      </geometry>
      <origin xyz="-0.774 -1.17 -0.81" rpy="0 0 0"/>
    </visual>
    <collision>
      <geometry>
        <mesh filename="file:///home/parsa/ros2_urdf_ws/src/my_robot_description/meshes//femur.dae" scale="0.01 0.01 0.01"/>
      </geometry>
      <origin xyz="-0.774 -1.17 -0.81" rpy="0 0 0"/>
    </collision>
      <inertial>
        <origin xyz="0.0 0.0 0.0" rpy="0.0 0.0 0.0"/>
        <mass value="0.006043"/>
        <inertia ixx="0.0000835711" ixy="0.00000010975" ixz="-0.000000004152" iyy="0.000000001607" iyz="-0.0002288" izz="-0.000000001607"/>
      </inertial>



  </link>

  <joint name="torso_b_1_femur_3" type="revolute">
    <parent link="torso_joint_b_1" />
    <child link="femur_3" />
    <origin xyz="0.193 0.23 -0.078" rpy="0 3.14 0"/>
    <axis xyz="1 0 0"/>
    <limit lower="-1.57" upper="1.57" velocity="100" effort="100"/>
  </joint>



  <link name="femur_4">
    <visual>  
      <geometry>
        <mesh filename="file:///home/parsa/ros2_urdf_ws/src/my_robot_description/meshes//femur.dae" scale="0.01 0.01 0.01"/>
      </geometry>
      <origin xyz="-0.774 -1.17 -0.81" rpy="0 0 0"/>
    </visual>
    <collision>
      <geometry>
        <mesh filename="file:///home/parsa/ros2_urdf_ws/src/my_robot_description/meshes//femur.dae" scale="0.01 0.01 0.01"/>
      </geometry>
      <origin xyz="-0.774 -1.17 -0.81" rpy="0 0 0"/>
    </collision>

      <inertial>
        <origin xyz="0.0 0.0 0.0" rpy="0.0 0.0 0.0"/>
        <mass value="0.006043"/>
        <inertia ixx="0.0000835711" ixy="0.00000010975" ixz="-0.000000004152" iyy="0.000000001607" iyz="-0.0002288" izz="-0.000000001607"/>
      </inertial>




  </link>

  <joint name="torso_b_2_femur_4" type="revolute">
    <parent link="torso_joint_b_2" />
    <child link="femur_4" />
    <origin xyz="0.193 0.23 -0.078" rpy="0 3.14 0"/>
    <axis xyz="1 0 0"/>
    <limit lower="-1.57" upper="1.57" velocity="100" effort="100"/>
  </joint>



  <link name="foot-f-1">
    <visual>  
      <geometry>
        <mesh filename="file:///home/parsa/ros2_urdf_ws/src/my_robot_description/meshes//foot-f-1.dae" scale="0.01 0.01 0.01"/>
      </geometry>
      <origin xyz="0.68 1.47 -0.75" rpy="0 0 3.14"/>
    </visual>
    <collision>
      <geometry>
        <mesh filename="file:///home/parsa/ros2_urdf_ws/src/my_robot_description/meshes//foot-f-1.dae" scale="0.01 0.01 0.01"/>
      </geometry>
      <origin xyz="0.68 1.47 -0.75" rpy="0 0 3.14"/>   
    </collision>

    <inertial>
      <origin xyz="0.0 0.0 0.0" rpy="0.0 0.0 0.0"/>
      <mass value="0.014414"/>
      <inertia ixx="0.0005637" ixy="-0.0000106943" ixz="-0.0000188535" iyy="0.0005966" iyz="-0.0000012977" izz="0.0001014"/>
    </inertial>
    


  </link>

  <joint name="foot-f-1_femur-1" type="revolute">
  <parent link="femur_1" />
  <child link="foot-f-1" />
    <origin xyz="-0.04 0.4 -0.02" rpy="0 0 3.14"/>
    <axis xyz="1 0 0"/>
    <limit lower="-1.57" upper="1.57" velocity="100" effort="100"/>
  </joint>


  <link name="foot-f-2">
    <visual>  
      <geometry>
        <mesh filename="file:///home/parsa/ros2_urdf_ws/src/my_robot_description/meshes//foot-f-1.dae" scale="0.01 0.01 0.01"/>
      </geometry>
      <origin xyz="0.68 1.47 -0.75" rpy="0 0 3.14"/>
    </visual>

    <collision>
      <geometry>
        <mesh filename="file:///home/parsa/ros2_urdf_ws/src/my_robot_description/meshes//foot-f-1.dae" scale="0.01 0.01 0.01"/>
      </geometry>
      <origin xyz="0.68 1.47 -0.75" rpy="0 0 3.14"/>    
    </collision>

    <inertial>
      <origin xyz="0.0 0.0 0.0" rpy="0.0 0.0 0.0"/>
      <mass value="0.014414"/>
      <inertia ixx="0.0005637" ixy="-0.0000106943" ixz="-0.0000188535" iyy="0.0005966" iyz="-0.0000012977" izz="0.0001014"/>
    </inertial>

  </link>

  <joint name="foot-f-2_femur-2" type="revolute">
  <parent link="femur_2" />
  <child link="foot-f-2" />
    <origin xyz="-0.023 0.38 -0.026" rpy="0 0 3.14"/>
    <axis xyz="1 0 0"/>
    <limit lower="-1.57" upper="1.57" velocity="100" effort="100"/>
  </joint>



  <link name="foot-b-1">
    <visual>  
      <geometry>
        <mesh filename="file:///home/parsa/ros2_urdf_ws/src/my_robot_description/meshes//foot-b-1.dae" scale="0.01 0.01 0.01"/>
      </geometry>
      <origin xyz="1.45 -1.37 0.84" rpy="-3.14 0 3.14"/>
    </visual>
    <collision>
      <geometry>
        <mesh filename="file:///home/parsa/ros2_urdf_ws/src/my_robot_description/meshes//foot-b-1.dae" scale="0.01 0.01 0.01"/>
      </geometry>
      <origin xyz="1.45 -1.37 0.84" rpy="-3.14 0 3.14"/>    
    </collision>
    <inertial>
      <origin xyz="0.0 0.0 0.0" rpy="0.0 0.0 0.0"/>
      <mass value="0.014474"/>
      <inertia ixx="0.0005555" ixy="0.0000026234" ixz="0.0000216591" iyy="0.0006032" iyz="0.0000061124" izz="0.0000981672"/>
    </inertial>


  </link>

  <joint name="foot-b-1_femur-3" type="revolute">
  <parent link="femur_3" />
  <child link="foot-b-1" />
    <origin xyz="-0.023 0.38 -0.026" rpy="0 0 0"/>
    <axis xyz="1 0 0"/>
    <limit lower="-1.57" upper="1.57" velocity="100" effort="100"/>
  </joint>



  <link name="foot-b-2">
    <visual>  
      <geometry>
        <mesh filename="file:///home/parsa/ros2_urdf_ws/src/my_robot_description/meshes//foot-b-1.dae" scale="0.01 0.01 0.01"/>
      </geometry>
      <origin xyz="1.45 -1.37 0.84" rpy="-3.14 0 3.14"/>
    </visual>
    <collision>
        <geometry>
        <mesh filename="file:///home/parsa/ros2_urdf_ws/src/my_robot_description/meshes//foot-b-1.dae" scale="0.01 0.01 0.01"/>
      </geometry>
      <origin xyz="1.45 -1.37 0.84" rpy="-3.14 0 3.14"/>  
    </collision>
    <inertial>
      <origin xyz="0.0 0.0 0.0" rpy="0.0 0.0 0.0"/>
      <mass value="0.014474"/>
      <inertia ixx="0.0005555" ixy="0.0000026234" ixz="0.0000216591" iyy="0.0006032" iyz="0.0000061124" izz="0.0000981672"/>
    </inertial>



  </link>

  <joint name="foot-b-2_femur-4" type="revolute">
  <parent link="femur_4" />
  <child link="foot-b-2" />
    <origin xyz="-0.023 0.38 -0.026" rpy="0 0 0"/>
    <axis xyz="1 0 0"/>
    <limit lower="-1.57" upper="1.57" velocity="100" effort="100"/>
  </joint>

<!-- <ros2_control name="GazeboSystem" type="system">
  <hardware>
    <plugin>gazebo_ros2_control/GazeboSystem</plugin>
  </hardware>
  <joint name="base_torso_f_1">
    <command_interface name="position">
      <param name="min">-1.57</param>
      <param name="max">1.57</param>
    </command_interface>
    <state_interface name="position">
      <param name="initial_value">0</param>
    </state_interface>
    <state_interface name="velocity"/>
    <state_interface name="effort"/>
  </joint>


  <joint name="base_torso_f_2>">
    <command_interface name="position">
      <param name="min">-1.57</param>
      <param name="max">1.57</param>
    </command_interface>
    <state_interface name="position">
      <param name="initial_value">0</param>
    </state_interface>
    <state_interface name="velocity"/>
    <state_interface name="effort"/>
  </joint>
  
  <joint name="base_torso_b_1>">
    <command_interface name="position">
      <param name="min">-1.57</param>
      <param name="max">1.57</param>
    </command_interface>
    <state_interface name="position">
      <param name="initial_value">0</param>
    </state_interface>
    <state_interface name="velocity"/>
    <state_interface name="effort"/>
  </joint>


  <joint name="base_torso_b_2>">
    <command_interface name="position">
      <param name="min">-1.57</param>
      <param name="max">1.57</param>
    </command_interface>
    <state_interface name="position">
      <param name="initial_value">0</param>
    </state_interface>
    <state_interface name="velocity"/>
    <state_interface name="effort"/>
  </joint>
</ros2_control>

<gazebo>
  <plugin filenmae="libgazebo_ros2_control.so" name="gazebo_ros2_control">
    <parameters>"file:///home/parsa/ros2_urdf_ws/src/my_robot_bringup/config/joint_controller.yaml" </parameters>
  </plugin>  

</gazebo> -->
</robot>